<?xml version="1.0" encoding="utf-8"?>
<!-- This URDF was automatically created by SolidWorks to URDF Exporter! Originally created by Stephen Brawner (brawner@gmail.com) 
     Commit Version: 1.5.1-0-g916b5db  Build Version: 1.5.7152.31018
     For more information, please see http://wiki.ros.org/sw_urdf_exporter -->
<robot
  name="roverfull2">
  <link
    name="base_link">
    <inertial>
      <origin
        xyz="0.390627992903174 -0.225000826679294 -0.00524116047614487"
        rpy="0 0 0" />
      <mass
        value="8.92481432729179" />
      <inertia
        ixx="0.200927778659357"
        ixy="-2.38445862202872E-08"
        ixz="7.49568682625905E-07"
        iyy="0.287176443590852"
        iyz="3.656663839131E-07"
        izz="0.236578408670972" />
    </inertial>
    <visual>
      <origin
        xyz="0 0 0"
        rpy="0 0 0" />
      <geometry>
        <mesh
          filename="package://roverfull2/meshes/base_link.STL" />
      </geometry>
      <material
        name="">
        <color
          rgba="0.898039215686275 0.917647058823529 0.929411764705882 1" />
      </material>
    </visual>
    <collision>
      <origin
        xyz="0 0 0"
        rpy="0 0 0" />
      <geometry>
        <mesh
          filename="package://roverfull2/meshes/base_link.STL" />
      </geometry>
    </collision>
  </link>
  <link
    name="frocker_r">
    <inertial>
      <origin
        xyz="-0.00592561850503992 -0.204564345826269 -0.656868984407299"
        rpy="0 0 0" />
      <mass
        value="3.62808269849788" />
      <inertia
        ixx="0.00500906208576131"
        ixy="5.33501708978563E-05"
        ixz="9.53784206745594E-06"
        iyy="0.00567797312385159"
        iyz="2.0106263766519E-06"
        izz="0.00521828016258716" />
    </inertial>
    <visual>
      <origin
        xyz="0 0 0"
        rpy="0 0 0" />
      <geometry>
        <mesh
          filename="package://roverfull2/meshes/frocker_r.STL" />
      </geometry>
      <material
        name="">
        <color
          rgba="0.898039215686275 0.917647058823529 0.929411764705882 1" />
      </material>
    </visual>
    <collision>
      <origin
        xyz="0 0 0"
        rpy="0 0 0" />
      <geometry>
        <mesh
          filename="package://roverfull2/meshes/frocker_r.STL" />
      </geometry>
    </collision>
  </link>
  <joint
    name="frocker_r_rev"
    type="revolute">
    <origin
      xyz="0.50364 0.1 -0.1463"
      rpy="1.5708 0 3.1416" />
    <parent
      link="base_link" />
    <child
      link="frocker_r" />
    <axis
      xyz="0 0 1" />
    <limit
      lower="0"
      upper="3.14"
      effort="0"
      velocity="0" />
  </joint>
  <link
    name="fwheel_r">
    <inertial>
      <origin
        xyz="6.60280705666594E-08 1.77122568278953E-08 -0.126320037033365"
        rpy="0 0 0" />
      <mass
        value="4.57641810426622" />
      <inertia
        ixx="0.0229681622888871"
        ixy="4.71906040971652E-05"
        ixz="-2.21722566896218E-09"
        iyy="0.0228054415849527"
        iyz="-3.99949402829746E-10"
        izz="0.0411576023588561" />
    </inertial>
    <visual>
      <origin
        xyz="0 0 0"
        rpy="0 0 0" />
      <geometry>
        <mesh
          filename="package://roverfull2/meshes/fwheel_r.STL" />
      </geometry>
      <material
        name="">
        <color
          rgba="0.792156862745098 0.819607843137255 0.933333333333333 1" />
      </material>
    </visual>
    <collision>
      <origin
        xyz="0 0 0"
        rpy="0 0 0" />
      <geometry>
        <mesh
          filename="package://roverfull2/meshes/fwheel_r.STL" />
      </geometry>
    </collision>
  </link>
  <joint
    name="fwheel_r_con"
    type="continuous">
    <origin
      xyz="-0.19005 -0.22827 -0.54388"
      rpy="0 0 0" />
    <parent
      link="frocker_r" />
    <child
      link="fwheel_r" />
    <axis
      xyz="0 0 1" />
    <limit
      lower="0"
      upper="3.14"
      effort="0"
      velocity="0" />
  </joint>
  <link
    name="mwheel_r">
    <inertial>
      <origin
        xyz="-5.91610797573416E-08 -3.4708003748829E-08 -0.130204609714562"
        rpy="0 0 0" />
      <mass
        value="4.57641810426621" />
      <inertia
        ixx="0.0229326959626408"
        ixy="8.20987129982453E-05"
        ixz="1.61130509180759E-09"
        iyy="0.022840907911199"
        iyz="1.21730207369358E-09"
        izz="0.0411576023588561" />
    </inertial>
    <visual>
      <origin
        xyz="0 0 0"
        rpy="0 0 0" />
      <geometry>
        <mesh
          filename="package://roverfull2/meshes/mwheel_r.STL" />
      </geometry>
      <material
        name="">
        <color
          rgba="0.792156862745098 0.819607843137255 0.933333333333333 1" />
      </material>
    </visual>
    <collision>
      <origin
        xyz="0 0 0"
        rpy="0 0 0" />
      <geometry>
        <mesh
          filename="package://roverfull2/meshes/mwheel_r.STL" />
      </geometry>
    </collision>
  </link>
  <joint
    name="mwheel_r_con"
    type="continuous">
    <origin
      xyz="0.15245 -0.25777 -0.58"
      rpy="0 0 0" />
    <parent
      link="frocker_r" />
    <child
      link="mwheel_r" />
    <axis
      xyz="0 0 1" />
    <limit
      lower="0"
      upper="3.14"
      effort="0"
      velocity="0" />
  </joint>
  <link
    name="frocker_l">
    <inertial>
      <origin
        xyz="-0.00944405559356859 -0.204322904220464 0.0068689884045614"
        rpy="0 0 0" />
      <mass
        value="3.62808311441716" />
      <inertia
        ixx="0.00500449356721194"
        ixy="-1.30696556999636E-06"
        ixz="8.94906673392479E-06"
        iyy="0.00568254172043279"
        iyz="-3.1191050104107E-06"
        izz="0.00521828016321352" />
    </inertial>
    <visual>
      <origin
        xyz="0 0 0"
        rpy="0 0 0" />
      <geometry>
        <mesh
          filename="package://roverfull2/meshes/frocker_l.STL" />
      </geometry>
      <material
        name="">
        <color
          rgba="0.898039215686275 0.917647058823529 0.929411764705882 1" />
      </material>
    </visual>
    <collision>
      <origin
        xyz="0 0 0"
        rpy="0 0 0" />
      <geometry>
        <mesh
          filename="package://roverfull2/meshes/frocker_l.STL" />
      </geometry>
    </collision>
  </link>
  <joint
    name="frocker_l_rev"
    type="revolute">
    <origin
      xyz="0.50364 0.1 -0.1463"
      rpy="1.5708 0 3.1416" />
    <parent
      link="base_link" />
    <child
      link="frocker_l" />
    <axis
      xyz="0 0 1" />
    <limit
      lower="0"
      upper="3.14"
      effort="0"
      velocity="0" />
  </joint>
  <link
    name="fwheel_l">
    <inertial>
      <origin
        xyz="-3.55382518135716E-08 5.84587941387937E-08 0.126320037033357"
        rpy="0 0 0" />
      <mass
        value="4.57641810426621" />
      <inertia
        ixx="0.0228437540468819"
        ixy="-8.36261814329286E-05"
        ixz="-1.14974303985051E-09"
        iyy="0.0229298498269578"
        iyz="1.54141616208056E-09"
        izz="0.0411576023588559" />
    </inertial>
    <visual>
      <origin
        xyz="0 0 0"
        rpy="0 0 0" />
      <geometry>
        <mesh
          filename="package://roverfull2/meshes/fwheel_l.STL" />
      </geometry>
      <material
        name="">
        <color
          rgba="0.792156862745098 0.819607843137255 0.933333333333333 1" />
      </material>
    </visual>
    <collision>
      <origin
        xyz="0 0 0"
        rpy="0 0 0" />
      <geometry>
        <mesh
          filename="package://roverfull2/meshes/fwheel_l.STL" />
      </geometry>
    </collision>
  </link>
  <joint
    name="fwheel_l_con"
    type="continuous">
    <origin
      xyz="-0.171879220613578 -0.242247640559571 -0.1061154273188"
      rpy="0 0 0" />
    <parent
      link="frocker_l" />
    <child
      link="fwheel_l" />
    <axis
      xyz="0 0 1" />
    <limit
      lower="0"
      upper="3.14"
      effort="0"
      velocity="0" />
  </joint>
  <link
    name="mwheel_l">
    <inertial>
      <origin
        xyz="-2.78106582207727E-08 6.24824634254395E-08 0.130204609714557"
        rpy="0 0 0" />
      <mass
        value="4.57641810426622" />
      <inertia
        ixx="0.022824026705411"
        ixy="-7.00409145902802E-05"
        ixz="-9.92031522046047E-10"
        iyy="0.0229495771684287"
        iyz="1.70143609867433E-09"
        izz="0.0411576023588559" />
    </inertial>
    <visual>
      <origin
        xyz="0 0 0"
        rpy="0 0 0" />
      <geometry>
        <mesh
          filename="package://roverfull2/meshes/mwheel_l.STL" />
      </geometry>
      <material
        name="">
        <color
          rgba="0.898039215686275 0.917647058823529 0.929411764705882 1" />
      </material>
    </visual>
    <collision>
      <origin
        xyz="0 0 0"
        rpy="0 0 0" />
      <geometry>
        <mesh
          filename="package://roverfull2/meshes/mwheel_l.STL" />
      </geometry>
    </collision>
  </link>
  <joint
    name="mwheel_l_con"
    type="continuous">
    <origin
      xyz="0.171879220613583 -0.245997640559572 -0.0699999999999998"
      rpy="0 0 0" />
    <parent
      link="frocker_l" />
    <child
      link="mwheel_l" />
    <axis
      xyz="0 0 1" />
    <limit
      lower="0"
      upper="3.14"
      effort="0"
      velocity="0" />
  </joint>
  <link
    name="brocker">
    <inertial>
      <origin
        xyz="-0.0762121804734911 -0.224999997620734 -0.362720491575227"
        rpy="0 0 0" />
      <mass
        value="3.58373396869916" />
      <inertia
        ixx="0.00608413831974133"
        ixy="-8.75712717051838E-06"
        ixz="-1.71200148472069E-06"
        iyy="0.00375597876242283"
        iyz="3.88057182040724E-06"
        izz="0.00574617112204382" />
    </inertial>
    <visual>
      <origin
        xyz="0 0 0"
        rpy="0 0 0" />
      <geometry>
        <mesh
          filename="package://roverfull2/meshes/brocker.STL" />
      </geometry>
      <material
        name="">
        <color
          rgba="0.898039215686275 0.917647058823529 0.929411764705882 1" />
      </material>
    </visual>
    <collision>
      <origin
        xyz="0 0 0"
        rpy="0 0 0" />
      <geometry>
        <mesh
          filename="package://roverfull2/meshes/brocker.STL" />
      </geometry>
    </collision>
  </link>
  <joint
    name="brocker_rev"
    type="revolute">
    <origin
      xyz="0 0 0"
      rpy="0 0 0" />
    <parent
      link="base_link" />
    <child
      link="brocker" />
    <axis
      xyz="1 0 0" />
    <limit
      lower="0"
      upper="3.14"
      effort="0"
      velocity="0" />
  </joint>
  <link
    name="bwheel_r">
    <inertial>
      <origin
        xyz="5.59375761266523E-08 3.9292225750831E-08 -0.127204609714562"
        rpy="0 0 0" />
      <mass
        value="4.57641810426623" />
      <inertia
        ixx="0.0229187940524817"
        ixy="8.84475250672531E-05"
        ixz="-1.84713279061157E-09"
        iyy="0.0228548098213584"
        iyz="-9.93983410456802E-10"
        izz="0.0411576023588562" />
    </inertial>
    <visual>
      <origin
        xyz="0 0 0"
        rpy="0 0 0" />
      <geometry>
        <mesh
          filename="package://roverfull2/meshes/bwheel_r.STL" />
      </geometry>
      <material
        name="">
        <color
          rgba="0.792156862745098 0.819607843137255 0.933333333333333 1" />
      </material>
    </visual>
    <collision>
      <origin
        xyz="0 0 0"
        rpy="0 0 0" />
      <geometry>
        <mesh
          filename="package://roverfull2/meshes/bwheel_r.STL" />
      </geometry>
    </collision>
  </link>
  <joint
    name="bwheel_r_con"
    type="continuous">
    <origin
      xyz="-0.0753999999999999 -0.4438845726812 -0.393799999999996"
      rpy="1.5707963267949 0 3.14159265358979" />
    <parent
      link="brocker" />
    <child
      link="bwheel_r" />
    <axis
      xyz="0 0 1" />
    <limit
      lower="0"
      upper="3.14"
      effort="0"
      velocity="0" />
  </joint>
  <link
    name="bwheel_l">
    <inertial>
      <origin
        xyz="-1.75642475008786E-08 6.60826227627531E-08 0.12720460971456"
        rpy="0 0 0" />
      <mass
        value="4.57641810426623" />
      <inertia
        ixx="0.0228052535039748"
        ixy="-4.68648354323432E-05"
        ixz="-7.40112139987691E-10"
        iyy="0.022968350369865"
        iyz="1.87284569616534E-09"
        izz="0.041157602358856" />
    </inertial>
    <visual>
      <origin
        xyz="0 0 0"
        rpy="0 0 0" />
      <geometry>
        <mesh
          filename="package://roverfull2/meshes/bwheel_l.STL" />
      </geometry>
      <material
        name="">
        <color
          rgba="0.792156862745098 0.819607843137255 0.933333333333333 1" />
      </material>
    </visual>
    <collision>
      <origin
        xyz="0 0 0"
        rpy="0 0 0" />
      <geometry>
        <mesh
          filename="package://roverfull2/meshes/bwheel_l.STL" />
      </geometry>
    </collision>
  </link>
  <joint
    name="bwheel_l_con"
    type="continuous">
    <origin
      xyz="-0.0753999999999954 -0.00611542731880199 -0.393799999999983"
      rpy="1.5707963267949 0 3.14159265358979" />
    <parent
      link="brocker" />
    <child
      link="bwheel_l" />
    <axis
      xyz="0 0 1" />
    <limit
      lower="0"
      upper="3.14"
      effort="0"
      velocity="0" />
  </joint>
  <link
    name="arm_1">
    <inertial>
      <origin
        xyz="0.758284098877497 -0.224998622573153 0.475864732604351"
        rpy="0 0 0" />
      <mass
        value="1.97622844031206" />
      <inertia
        ixx="0.00130588627630206"
        ixy="1.84105199324513E-08"
        ixz="2.44483516668304E-05"
        iyy="0.0145858160715925"
        iyz="-2.48783800342458E-08"
        izz="0.015315143760798" />
    </inertial>
    <visual>
      <origin
        xyz="0 0 0"
        rpy="0 0 0" />
      <geometry>
        <mesh
          filename="package://roverfull2/meshes/arm_1.STL" />
      </geometry>
      <material
        name="">
        <color
          rgba="0.898039215686275 0.917647058823529 0.929411764705882 1" />
      </material>
    </visual>
    <collision>
      <origin
        xyz="0 0 0"
        rpy="0 0 0" />
      <geometry>
        <mesh
          filename="package://roverfull2/meshes/arm_1.STL" />
      </geometry>
    </collision>
  </link>
  <joint
    name="arm_1_pri"
    type="prismatic">
    <origin
      xyz="0 0 0"
      rpy="0 0 0" />
    <parent
      link="base_link" />
    <child
      link="arm_1" />
    <axis
      xyz="0 0 -1" />
    <limit
      lower="-0.3"
      upper="0.06"
      effort="0"
      velocity="0" />
  </joint>
  <link
    name="arm_2">
    <inertial>
      <origin
        xyz="1.07581673794265 -0.225000032723442 0.471033171543102"
        rpy="0 0 0" />
      <mass
        value="2.01149065259503" />
      <inertia
        ixx="0.00481583912868421"
        ixy="-2.30028487857025E-09"
        ixz="8.75882659858047E-06"
        iyy="0.00223882197928408"
        iyz="4.76930240531077E-12"
        izz="0.00680854703925199" />
    </inertial>
    <visual>
      <origin
        xyz="0 0 0"
        rpy="0 0 0" />
      <geometry>
        <mesh
          filename="package://roverfull2/meshes/arm_2.STL" />
      </geometry>
      <material
        name="">
        <color
          rgba="0.898039215686275 0.917647058823529 0.929411764705882 1" />
      </material>
    </visual>
    <collision>
      <origin
        xyz="0 0 0"
        rpy="0 0 0" />
      <geometry>
        <mesh
          filename="package://roverfull2/meshes/arm_2.STL" />
      </geometry>
    </collision>
  </link>
  <joint
    name="arm_2_pri"
    type="prismatic">
    <origin
      xyz="0 0 0"
      rpy="0 0 0" />
    <parent
      link="arm_1" />
    <child
      link="arm_2" />
    <axis
      xyz="-1 0 0" />
    <limit
      lower="-0.15"
      upper="0.02"
      effort="0"
      velocity="0" />
  </joint>
  <link
    name="arm_3">
    <inertial>
      <origin
        xyz="0.11616967785363 0.0192309602616632 5.28751820105811E-10"
        rpy="0 0 0" />
      <mass
        value="0.2134325834612" />
      <inertia
        ixx="9.22086821479591E-05"
        ixy="-5.38021185624505E-06"
        ixz="9.11798672894074E-12"
        iyy="0.0010645504874968"
        iyz="8.22887492816649E-13"
        izz="0.00101495891687128" />
    </inertial>
    <visual>
      <origin
        xyz="0 0 0"
        rpy="0 0 0" />
      <geometry>
        <mesh
          filename="package://roverfull2/meshes/arm_3.STL" />
      </geometry>
      <material
        name="">
        <color
          rgba="0.898039215686275 0.917647058823529 0.929411764705882 1" />
      </material>
    </visual>
    <collision>
      <origin
        xyz="0 0 0"
        rpy="0 0 0" />
      <geometry>
        <mesh
          filename="package://roverfull2/meshes/arm_3.STL" />
      </geometry>
    </collision>
  </link>
  <joint
    name="arm_3_rev"
    type="revolute">
    <origin
      xyz="1.09406614726591 -0.224999999999987 0.376149999999977"
      rpy="1.5707963267949 0 -0.117391442296921" />
    <parent
      link="arm_2" />
    <child
      link="arm_3" />
    <axis
      xyz="0 -1 0" />
    <limit
      lower="-3.14"
      upper="3.14"
      effort="0"
      velocity="0" />
  </joint>
  <link
    name="arm_4">
    <inertial>
      <origin
        xyz="0.0507999999974929 -0.063638898515562 -0.0475773388143453"
        rpy="0 0 0" />
      <mass
        value="0.157002726479324" />
      <inertia
        ixx="8.76040768024603E-05"
        ixy="1.18207659154801E-11"
        ixz="4.52024188800961E-11"
        iyy="6.7960685181663E-05"
        iyz="-2.68157898203755E-06"
        izz="9.44845885245056E-05" />
    </inertial>
    <visual>
      <origin
        xyz="0 0 0"
        rpy="0 0 0" />
      <geometry>
        <mesh
          filename="package://roverfull2/meshes/arm_4.STL" />
      </geometry>
      <material
        name="">
        <color
          rgba="0.792156862745098 0.819607843137255 0.933333333333333 1" />
      </material>
    </visual>
    <collision>
      <origin
        xyz="0 0 0"
        rpy="0 0 0" />
      <geometry>
        <mesh
          filename="package://roverfull2/meshes/arm_4.STL" />
      </geometry>
    </collision>
  </link>
  <joint
    name="arm_4_rev"
    type="revolute">
    <origin
      xyz="0.218000000000006 -0.0260000000000016 0.0508000000000022"
      rpy="0 1.5707963267949 0" />
    <parent
      link="arm_3" />
    <child
      link="arm_4" />
    <axis
      xyz="-1 0 0" />
    <limit
      lower="0"
      upper="3.14"
      effort="0"
      velocity="0" />
  </joint>
  <link
    name="arm_5">
    <inertial>
      <origin
        xyz="0.0437981528600424 -0.0413542909914428 0.0315314071150152"
        rpy="0 0 0" />
      <mass
        value="0.371561862036471" />
      <inertia
        ixx="8.04531778734177E-05"
        ixy="2.71846417948633E-07"
        ixz="2.03243749180377E-07"
        iyy="0.000695815523736749"
        iyz="6.88585460404746E-07"
        izz="0.00069829257579992" />
    </inertial>
    <visual>
      <origin
        xyz="0 0 0"
        rpy="0 0 0" />
      <geometry>
        <mesh
          filename="package://roverfull2/meshes/arm_5.STL" />
      </geometry>
      <material
        name="">
        <color
          rgba="0.792156862745098 0.819607843137255 0.933333333333333 1" />
      </material>
    </visual>
    <collision>
      <origin
        xyz="0 0 0"
        rpy="0 0 0" />
      <geometry>
        <mesh
          filename="package://roverfull2/meshes/arm_5.STL" />
      </geometry>
    </collision>
  </link>
  <joint
    name="arm_5_rev"
    type="revolute">
    <origin
      xyz="0.0508 -0.12945 -0.030155"
      rpy="-0.14249 0.69562 -0.22023" />
    <parent
      link="arm_4" />
    <child
      link="arm_5" />
    <axis
      xyz="0 -0.98132 0.19236" />
    <limit
      lower="0"
      upper="3.14"
      effort="0"
      velocity="0" />
  </joint>
  <link
    name="finger_1">
    <inertial>
      <origin
        xyz="1.35743023645333 -0.307257373860656 0.0997263361058026"
        rpy="0 0 0" />
      <mass
        value="0.16990761907047" />
      <inertia
        ixx="4.32309067444289E-05"
        ixy="3.40680570740019E-06"
        ixz="3.86826965031035E-06"
        iyy="4.08701285603207E-05"
        iyz="2.9907995400991E-06"
        izz="2.13040675558832E-05" />
    </inertial>
    <visual>
      <origin
        xyz="0 0 0"
        rpy="0 0 0" />
      <geometry>
        <mesh
          filename="package://roverfull2/meshes/finger_1.STL" />
      </geometry>
      <material
        name="">
        <color
          rgba="0.498039215686275 0.498039215686275 0.498039215686275 1" />
      </material>
    </visual>
    <collision>
      <origin
        xyz="0 0 0"
        rpy="0 0 0" />
      <geometry>
        <mesh
          filename="package://roverfull2/meshes/finger_1.STL" />
      </geometry>
    </collision>
  </link>
  <joint
    name="finger_1_pri"
    type="prismatic">
    <origin
      xyz="0.941996262521212 -0.0636309720354219 -0.926442486473448"
      rpy="1.5707963267949 -0.980519680528883 -2.97309974796777" />
    <parent
      link="arm_5" />
    <child
      link="finger_1" />
    <axis
      xyz="-0.548708784039424 0.819021646560213 -0.167696788233332" />
    <limit
      lower="0"
      upper="0.03"
      effort="0"
      velocity="0" />
  </joint>
  <link
    name="finger_2">
    <inertial>
      <origin
        xyz="1.28151600097203 -0.193944635537133 0.0765237092505957"
        rpy="0 0 0" />
      <mass
        value="0.169907626108929" />
      <inertia
        ixx="4.14627570140935E-05"
        ixy="4.83179492497717E-06"
        ixz="7.00145916731703E-06"
        iyy="4.05577815301428E-05"
        iyz="-2.06045387036006E-06"
        izz="2.33845655134681E-05" />
    </inertial>
    <visual>
      <origin
        xyz="0 0 0"
        rpy="0 0 0" />
      <geometry>
        <mesh
          filename="package://roverfull2/meshes/finger_2.STL" />
      </geometry>
      <material
        name="">
        <color
          rgba="0.498039215686275 0.498039215686275 0.498039215686275 1" />
      </material>
    </visual>
    <collision>
      <origin
        xyz="0 0 0"
        rpy="0 0 0" />
      <geometry>
        <mesh
          filename="package://roverfull2/meshes/finger_2.STL" />
      </geometry>
    </collision>
  </link>
  <joint
    name="finger_2_pri"
    type="prismatic">
    <origin
      xyz="0.941996262521212 -0.0636309720354219 -0.926442486473448"
      rpy="1.5707963267949 -0.980519680528883 -2.97309974796777" />
    <parent
      link="arm_5" />
    <child
      link="finger_2" />
    <axis
      xyz="-0.548708784039424 0.819021646560213 -0.167696788233332" />
    <limit
      lower="0"
      upper="0.04"
      effort="0"
      velocity="0" />
  </joint>
</robot>
